<robot name="simple_niryo">

    <material name="blue">
        <color rgba="0.192157 0.643137 0.866667 1"/>
    </material>

    <!-- WORLD -->
    <link name="world"/>

    <!-- [REQUIRED] BASE LINK -->
    <link name="base_link">
        <visual>
            <geometry>
                <box size="0.25 0.25 0.15"/>
            </geometry>
            <origin rpy="0 0 0" xyz="0 0 0.075"/>
            <material name="blue"/>
        </visual>
    </link>
    <joint name="world_to_base_link_joint" type="fixed">
        <parent link="world"/>
        <child link="base_link"/>
        <origin rpy="0 0 0" xyz="0 0 0"/>
    </joint>
    
    <!-- SHOULDER LINK -->
    <link name="shoulder_link">
        <visual>
            <geometry>
                <cylinder length="0.15" radius="0.1"/>
            </geometry>
            <origin rpy="0 0 0" xyz="0 0 0.075"/>
            <material name="blue"/>
        </visual>
    </link>
    <joint name="base_to_shoulder_joint" type="revolute">
        <parent link="base_link"/>
        <child link="shoulder_link"/>
        <origin rpy="0 0 0" xyz="0 0 0.15"/>
        <axis xyz="0 0 1"/>
        <limit effort="1000.0" lower="-${radians(150.0)}" upper="${radians(150.0)}" velocity="0.5"/>
    </joint>

</robot>
